<?xml version="1.0" encoding="UTF-8"?>
<testng-results skipped="0" failed="2" ignored="0" retried="2" total="6" passed="2">
  <reporter-output>
  </reporter-output>
  <suite name="customListener_reRunFailedtests Suite" duration-ms="45" started-at="2021-09-11T01:04:18 IST" finished-at="2021-09-11T01:04:18 IST">
    <groups>
    </groups>
    <test name="CustomListener_reRunFailedtest Test" duration-ms="45" started-at="2021-09-11T01:04:18 IST" finished-at="2021-09-11T01:04:18 IST">
      <class name="_41_3_TestNG_Listeners.IRetryAnalyzer_Re_RunFailed_Tests.TestCases">
        <test-method status="PASS" signature="TC_01()[pri:0, instance:_41_3_TestNG_Listeners.IRetryAnalyzer_Re_RunFailed_Tests.TestCases@d44fc21]" name="TC_01" duration-ms="6" started-at="2021-09-11T01:04:18 IST" finished-at="2021-09-11T01:04:18 IST">
          <reporter-output>
          </reporter-output>
        </test-method> <!-- TC_01 -->
        <test-method status="PASS" signature="TC_02()[pri:0, instance:_41_3_TestNG_Listeners.IRetryAnalyzer_Re_RunFailed_Tests.TestCases@d44fc21]" name="TC_02" duration-ms="1" started-at="2021-09-11T01:04:18 IST" finished-at="2021-09-11T01:04:18 IST">
          <reporter-output>
          </reporter-output>
        </test-method> <!-- TC_02 -->
        <test-method status="SKIP" signature="TC_03()[pri:0, instance:_41_3_TestNG_Listeners.IRetryAnalyzer_Re_RunFailed_Tests.TestCases@d44fc21]" name="TC_03" duration-ms="2" retried="true" started-at="2021-09-11T01:04:18 IST" finished-at="2021-09-11T01:04:18 IST">
          <exception class="java.lang.AssertionError">
            <message>
              <![CDATA[Failing TC_03]]>
            </message>
            <full-stacktrace>
              <![CDATA[java.lang.AssertionError: Failing TC_03
at org.testng.Assert.fail(Assert.java:97)
at _41_3_TestNG_Listeners.IRetryAnalyzer_Re_RunFailed_Tests.TestCases.TC_03(TestCases.java:19)
at sun.reflect.NativeMethodAccessorImpl.invoke0(Native Method)
at sun.reflect.NativeMethodAccessorImpl.invoke(NativeMethodAccessorImpl.java:62)
at sun.reflect.DelegatingMethodAccessorImpl.invoke(DelegatingMethodAccessorImpl.java:43)
at java.lang.reflect.Method.invoke(Method.java:498)
at org.testng.internal.MethodInvocationHelper.invokeMethod(MethodInvocationHelper.java:134)
at org.testng.internal.TestInvoker.invokeMethod(TestInvoker.java:597)
at org.testng.internal.TestInvoker.invokeTestMethod(TestInvoker.java:173)
at org.testng.internal.MethodRunner.runInSequence(MethodRunner.java:46)
at org.testng.internal.TestInvoker$MethodInvocationAgent.invoke(TestInvoker.java:816)
at org.testng.internal.TestInvoker.invokeTestMethods(TestInvoker.java:146)
at org.testng.internal.TestMethodWorker.invokeTestMethods(TestMethodWorker.java:146)
at org.testng.internal.TestMethodWorker.run(TestMethodWorker.java:128)
at java.util.ArrayList.forEach(ArrayList.java:1259)
at org.testng.TestRunner.privateRun(TestRunner.java:766)
at org.testng.TestRunner.run(TestRunner.java:587)
at org.testng.SuiteRunner.runTest(SuiteRunner.java:384)
at org.testng.SuiteRunner.runSequentially(SuiteRunner.java:378)
at org.testng.SuiteRunner.privateRun(SuiteRunner.java:337)
at org.testng.SuiteRunner.run(SuiteRunner.java:286)
at org.testng.SuiteRunnerWorker.runSuite(SuiteRunnerWorker.java:53)
at org.testng.SuiteRunnerWorker.run(SuiteRunnerWorker.java:96)
at org.testng.TestNG.runSuitesSequentially(TestNG.java:1187)
at org.testng.TestNG.runSuitesLocally(TestNG.java:1109)
at org.testng.TestNG.runSuites(TestNG.java:1039)
at org.testng.TestNG.run(TestNG.java:1007)
at org.testng.remote.AbstractRemoteTestNG.run(AbstractRemoteTestNG.java:115)
at org.testng.remote.RemoteTestNG.initAndRun(RemoteTestNG.java:251)
at org.testng.remote.RemoteTestNG.main(RemoteTestNG.java:77)
]]>
            </full-stacktrace>
          </exception> <!-- java.lang.AssertionError -->
          <reporter-output>
          </reporter-output>
        </test-method> <!-- TC_03 -->
        <test-method status="FAIL" signature="TC_03()[pri:0, instance:_41_3_TestNG_Listeners.IRetryAnalyzer_Re_RunFailed_Tests.TestCases@d44fc21]" name="TC_03" duration-ms="1" started-at="2021-09-11T01:04:18 IST" finished-at="2021-09-11T01:04:18 IST">
          <exception class="java.lang.AssertionError">
            <message>
              <![CDATA[Failing TC_03]]>
            </message>
            <full-stacktrace>
              <![CDATA[java.lang.AssertionError: Failing TC_03
at org.testng.Assert.fail(Assert.java:97)
at _41_3_TestNG_Listeners.IRetryAnalyzer_Re_RunFailed_Tests.TestCases.TC_03(TestCases.java:19)
at sun.reflect.NativeMethodAccessorImpl.invoke0(Native Method)
at sun.reflect.NativeMethodAccessorImpl.invoke(NativeMethodAccessorImpl.java:62)
at sun.reflect.DelegatingMethodAccessorImpl.invoke(DelegatingMethodAccessorImpl.java:43)
at java.lang.reflect.Method.invoke(Method.java:498)
at org.testng.internal.MethodInvocationHelper.invokeMethod(MethodInvocationHelper.java:134)
at org.testng.internal.TestInvoker.invokeMethod(TestInvoker.java:597)
at org.testng.internal.TestInvoker.retryFailed(TestInvoker.java:213)
at org.testng.internal.MethodRunner.runInSequence(MethodRunner.java:58)
at org.testng.internal.TestInvoker$MethodInvocationAgent.invoke(TestInvoker.java:816)
at org.testng.internal.TestInvoker.invokeTestMethods(TestInvoker.java:146)
at org.testng.internal.TestMethodWorker.invokeTestMethods(TestMethodWorker.java:146)
at org.testng.internal.TestMethodWorker.run(TestMethodWorker.java:128)
at java.util.ArrayList.forEach(ArrayList.java:1259)
at org.testng.TestRunner.privateRun(TestRunner.java:766)
at org.testng.TestRunner.run(TestRunner.java:587)
at org.testng.SuiteRunner.runTest(SuiteRunner.java:384)
at org.testng.SuiteRunner.runSequentially(SuiteRunner.java:378)
at org.testng.SuiteRunner.privateRun(SuiteRunner.java:337)
at org.testng.SuiteRunner.run(SuiteRunner.java:286)
at org.testng.SuiteRunnerWorker.runSuite(SuiteRunnerWorker.java:53)
at org.testng.SuiteRunnerWorker.run(SuiteRunnerWorker.java:96)
at org.testng.TestNG.runSuitesSequentially(TestNG.java:1187)
at org.testng.TestNG.runSuitesLocally(TestNG.java:1109)
at org.testng.TestNG.runSuites(TestNG.java:1039)
at org.testng.TestNG.run(TestNG.java:1007)
at org.testng.remote.AbstractRemoteTestNG.run(AbstractRemoteTestNG.java:115)
at org.testng.remote.RemoteTestNG.initAndRun(RemoteTestNG.java:251)
at org.testng.remote.RemoteTestNG.main(RemoteTestNG.java:77)
]]>
            </full-stacktrace>
          </exception> <!-- java.lang.AssertionError -->
          <reporter-output>
          </reporter-output>
        </test-method> <!-- TC_03 -->
        <test-method status="SKIP" signature="TC_04()[pri:0, instance:_41_3_TestNG_Listeners.IRetryAnalyzer_Re_RunFailed_Tests.TestCases@d44fc21]" name="TC_04" duration-ms="1" retried="true" started-at="2021-09-11T01:04:18 IST" finished-at="2021-09-11T01:04:18 IST">
          <exception class="java.lang.AssertionError">
            <message>
              <![CDATA[Failing TC_04]]>
            </message>
            <full-stacktrace>
              <![CDATA[java.lang.AssertionError: Failing TC_04
at org.testng.Assert.fail(Assert.java:97)
at _41_3_TestNG_Listeners.IRetryAnalyzer_Re_RunFailed_Tests.TestCases.TC_04(TestCases.java:25)
at sun.reflect.NativeMethodAccessorImpl.invoke0(Native Method)
at sun.reflect.NativeMethodAccessorImpl.invoke(NativeMethodAccessorImpl.java:62)
at sun.reflect.DelegatingMethodAccessorImpl.invoke(DelegatingMethodAccessorImpl.java:43)
at java.lang.reflect.Method.invoke(Method.java:498)
at org.testng.internal.MethodInvocationHelper.invokeMethod(MethodInvocationHelper.java:134)
at org.testng.internal.TestInvoker.invokeMethod(TestInvoker.java:597)
at org.testng.internal.TestInvoker.invokeTestMethod(TestInvoker.java:173)
at org.testng.internal.MethodRunner.runInSequence(MethodRunner.java:46)
at org.testng.internal.TestInvoker$MethodInvocationAgent.invoke(TestInvoker.java:816)
at org.testng.internal.TestInvoker.invokeTestMethods(TestInvoker.java:146)
at org.testng.internal.TestMethodWorker.invokeTestMethods(TestMethodWorker.java:146)
at org.testng.internal.TestMethodWorker.run(TestMethodWorker.java:128)
at java.util.ArrayList.forEach(ArrayList.java:1259)
at org.testng.TestRunner.privateRun(TestRunner.java:766)
at org.testng.TestRunner.run(TestRunner.java:587)
at org.testng.SuiteRunner.runTest(SuiteRunner.java:384)
at org.testng.SuiteRunner.runSequentially(SuiteRunner.java:378)
at org.testng.SuiteRunner.privateRun(SuiteRunner.java:337)
at org.testng.SuiteRunner.run(SuiteRunner.java:286)
at org.testng.SuiteRunnerWorker.runSuite(SuiteRunnerWorker.java:53)
at org.testng.SuiteRunnerWorker.run(SuiteRunnerWorker.java:96)
at org.testng.TestNG.runSuitesSequentially(TestNG.java:1187)
at org.testng.TestNG.runSuitesLocally(TestNG.java:1109)
at org.testng.TestNG.runSuites(TestNG.java:1039)
at org.testng.TestNG.run(TestNG.java:1007)
at org.testng.remote.AbstractRemoteTestNG.run(AbstractRemoteTestNG.java:115)
at org.testng.remote.RemoteTestNG.initAndRun(RemoteTestNG.java:251)
at org.testng.remote.RemoteTestNG.main(RemoteTestNG.java:77)
]]>
            </full-stacktrace>
          </exception> <!-- java.lang.AssertionError -->
          <reporter-output>
          </reporter-output>
        </test-method> <!-- TC_04 -->
        <test-method status="FAIL" signature="TC_04()[pri:0, instance:_41_3_TestNG_Listeners.IRetryAnalyzer_Re_RunFailed_Tests.TestCases@d44fc21]" name="TC_04" duration-ms="1" started-at="2021-09-11T01:04:18 IST" finished-at="2021-09-11T01:04:18 IST">
          <exception class="java.lang.AssertionError">
            <message>
              <![CDATA[Failing TC_04]]>
            </message>
            <full-stacktrace>
              <![CDATA[java.lang.AssertionError: Failing TC_04
at org.testng.Assert.fail(Assert.java:97)
at _41_3_TestNG_Listeners.IRetryAnalyzer_Re_RunFailed_Tests.TestCases.TC_04(TestCases.java:25)
at sun.reflect.NativeMethodAccessorImpl.invoke0(Native Method)
at sun.reflect.NativeMethodAccessorImpl.invoke(NativeMethodAccessorImpl.java:62)
at sun.reflect.DelegatingMethodAccessorImpl.invoke(DelegatingMethodAccessorImpl.java:43)
at java.lang.reflect.Method.invoke(Method.java:498)
at org.testng.internal.MethodInvocationHelper.invokeMethod(MethodInvocationHelper.java:134)
at org.testng.internal.TestInvoker.invokeMethod(TestInvoker.java:597)
at org.testng.internal.TestInvoker.retryFailed(TestInvoker.java:213)
at org.testng.internal.MethodRunner.runInSequence(MethodRunner.java:58)
at org.testng.internal.TestInvoker$MethodInvocationAgent.invoke(TestInvoker.java:816)
at org.testng.internal.TestInvoker.invokeTestMethods(TestInvoker.java:146)
at org.testng.internal.TestMethodWorker.invokeTestMethods(TestMethodWorker.java:146)
at org.testng.internal.TestMethodWorker.run(TestMethodWorker.java:128)
at java.util.ArrayList.forEach(ArrayList.java:1259)
at org.testng.TestRunner.privateRun(TestRunner.java:766)
at org.testng.TestRunner.run(TestRunner.java:587)
at org.testng.SuiteRunner.runTest(SuiteRunner.java:384)
at org.testng.SuiteRunner.runSequentially(SuiteRunner.java:378)
at org.testng.SuiteRunner.privateRun(SuiteRunner.java:337)
at org.testng.SuiteRunner.run(SuiteRunner.java:286)
at org.testng.SuiteRunnerWorker.runSuite(SuiteRunnerWorker.java:53)
at org.testng.SuiteRunnerWorker.run(SuiteRunnerWorker.java:96)
at org.testng.TestNG.runSuitesSequentially(TestNG.java:1187)
at org.testng.TestNG.runSuitesLocally(TestNG.java:1109)
at org.testng.TestNG.runSuites(TestNG.java:1039)
at org.testng.TestNG.run(TestNG.java:1007)
at org.testng.remote.AbstractRemoteTestNG.run(AbstractRemoteTestNG.java:115)
at org.testng.remote.RemoteTestNG.initAndRun(RemoteTestNG.java:251)
at org.testng.remote.RemoteTestNG.main(RemoteTestNG.java:77)
]]>
            </full-stacktrace>
          </exception> <!-- java.lang.AssertionError -->
          <reporter-output>
          </reporter-output>
        </test-method> <!-- TC_04 -->
      </class> <!-- _41_3_TestNG_Listeners.IRetryAnalyzer_Re_RunFailed_Tests.TestCases -->
    </test> <!-- CustomListener_reRunFailedtest Test -->
  </suite> <!-- customListener_reRunFailedtests Suite -->
</testng-results>
